Workbook

Sheet metadata
A1: filename | B1: title | C1: date | D1: author | E1: tags | F1: tag_count | G1: new tags
A2: 2013-07-24-why-mobile-apps-web-are-so-slow.md | B2: Why Some Mobile Apps are So Slow | C2: 2013-07-24T00:00:07-06:00 | D2: Jim McKeeth | E2: Architecture (4) | F2: 1
A3: 2017-04-13-mvvm-mvc-rad-architectures-with-columbusegg4delphi.md | B3: MVVM-MVC-RAD Architectures with ColumbusEgg4Delphi | C3: 2017-04-13T15:48:58-06:00 | D3: Jim McKeeth | E3: Architecture (4) | F3: 1
A4: 2013-09-02-tips-for-solving-bugs.md | B4: Tips for Solving Bugs | C4: 2013-09-02T10:57:09-06:00 | D4: Jim McKeeth | E4: Article (7) | F4: 1 | G4: general
A5: 2016-06-02-what-is-delphis-dna.md | B5: What is Delphi?s DNA? | C5: 2016-06-02T19:52:24-06:00 | D5: Jim McKeeth | E5: Article (7) | F5: 1 | G5: general
A6: 2009-02-16-22-delphi-developer-days-2009.md | B6: 22 ? Delphi Developer Days 2009 | C6: 2009-02-16T18:34:44-07:00 | D6: Jim McKeeth | E6: Audio podCast (74) | F6: 1 | G6: audio podcast
A7: 2009-02-23-23-datarage-and-all-access.md | B7: 23 ? DataRage and All-Access | C7: 2009-02-23T00:59:04-07:00 | D7: Jim McKeeth | E7: Audio podCast (74) | F7: 1 | G7: audio podcast
A8: 2010-07-31-43-simon-kissel.md | B8: 43 ? Simon Kissel | C8: 2010-07-31T22:59:49-06:00 | D8: Jim McKeeth | E8: Audio podCast (74) | F8: 1 | G8: audio podcast
A9: 2012-02-21-49-gad-d-lord-and-mtg-studio.md | B9: 49 ? Gad D Lord and MTG Studio | C9: 2012-02-21T17:53:41-07:00 | D9: Jim McKeeth | E9: Audio podCast (74) | F9: 1 | G9: audio podcast
A10: 2012-05-29-50-tables-turned.md | B10: 50 ? Tables Turned | C10: 2012-05-29T21:50:48-06:00 | D10: Jim McKeeth | E10: Audio podCast (74) | F10: 1 | G10: audio podcast
A11: 2013-04-22-52-delphi-xe4-for-ios.md | B11: 52 ? Marco Cantu & Delphi XE4 for iOS | C11: 2013-04-22T22:02:37-06:00 | D11: Jim McKeeth | E11: Audio podCast (74) | F11: 1 | G11: audio podcast
A12: 2013-07-22-53-subject-33-android-game-development.md | B12: 53 ? Subject 33 & Android Game Development | C12: 2013-07-22T09:07:53-06:00 | D12: Jim McKeeth | E12: Audio podCast (74) | F12: 1 | G12: audio podcast
A13: 2013-07-22-also-on-the-tablet-show-2.md | B13: Also on the Tablet Show | C13: 2013-07-22T17:45:05-06:00 | D13: Jim McKeeth | E13: Audio podCast (74) | F13: 1 | G13: audio podcast
A14: 2018-03-14-google-cloud-shell-network-details.md | B14: Google Cloud Shell Network Details | C14: 2018-03-14T20:53:22-06:00 | D14: Jim McKeeth | E14: Cloud (3) | F14: 1
A15: 2013-08-02-programming-languages-not-0-sum.md | B15: Sum(Programming Languages) > 0 | C15: 2013-08-02T12:32:43-06:00 | D15: Jim McKeeth | E15: Commentary (4) | F15: 1 | G15: general
A16: 2014-08-06-how-to-get-answers-to-your-questions.md | B16: How to Get Answers to Your Questions | C16: 2014-08-06T19:47:31-06:00 | D16: Jim McKeeth | E16: Commentary (4) | F16: 1 | G16: general
A17: 2010-08-24-delphi-bots-live.md | B17: Delphi Bots Live! | C17: 2010-08-24T17:18:49-06:00 | D17: Jim McKeeth | E17: Conferences (15) | F17: 1
A18: 2011-08-22-conference-time.md | B18: Conference Time | C18: 2011-08-22T10:21:51-06:00 | D18: Jim McKeeth | E18: Conferences (15) | F18: 1
A19: 2013-10-03-coderage-8-is-coming.md | B19: CodeRage 8 Is Coming! | C19: 2013-10-03T18:23:27-06:00 | D19: Jim McKeeth | E19: Conferences (15) | F19: 1
A20: 2015-10-23-t-shirts-from-brazil-delphi-conference.md | B20: T-Shirts from Brazil Delphi Conference | C20: 2015-10-23T05:32:35-06:00 | D20: Jim McKeeth | E20: Conferences (15) | F20: 1
A21: 2014-05-26-know-your-alignments.md | B21: Know Your Alignments | C21: 2014-05-26T04:17:13-06:00 | D21: Jim McKeeth | E21: design (5) | F21: 1
A22: 2014-05-22-delphi-sensors-on-windows-8-tablet.md | B22: Delphi Sensors on Windows 8 Tablet | C22: 2014-05-22T09:26:47-06:00 | D22: Jim McKeeth | E22: devices (8) | F22: 1
A23: 2017-06-06-simple-mobile-firedac-app.md | B23: Simple Mobile FireDAC App | C23: 2017-06-06T04:07:39-06:00 | D23: Jim McKeeth | E23: FireDAC (5) | F23: 1
A24: 2013-10-02-6-stages-of-debugging.md | B24: 6 Stages of Debugging | C24: 2013-10-02T20:18:25-06:00 | D24: Jim McKeeth | E24: Funny (5) | F24: 1
A25: 2013-07-25-iphone-windows-os-x.md | B25: Directions to iPhone, Windows & OS X | C25: 2013-07-25T09:32:21-06:00 | D25: Jim McKeeth | E25: Graphics (4) | F25: 1
A26: 2013-09-24-delphi-xe5-android-wallpaper.md | B26: Delphi XE5 Android Wallpaper | C26: 2013-09-24T17:55:07-06:00 | D26: Jim McKeeth | E26: Graphics (4) | F26: 1
A27: 2014-11-18-what-is-the-internet-of-things.md | B27: What is the Internet of Things? | C27: 2014-11-18T16:17:01-07:00 | D27: Jim McKeeth | E27: Internet of Things (3) | F27: 1
A28: 2013-12-04-my-favorite-quote-from-the-xe5-tour.md | B28: My Favorite Quote from the XE5 Tour | C28: 2013-12-04T23:51:25-07:00 | D28: Jim McKeeth | E28: iOS (26) | F28: 1
... A38: 2017-03-23-meet-hosokawa-jun-our-japan-mvp.md | B38: Meet HOSOKAWA Jun, our Japan MVP | C38: 2017-03-23T12:14:24-06:00 | D38: Jim McKeeth | E38: MVP (30) | F38: 1
A39: 2008-08-18-now-on-itunes.md | B39: Now on iTunes | C39: 2008-08-18T15:43:14-06:00 | D39: Jim McKeeth | E39: News (232) | F39: 1 | G39: general
A40: 2008-09-05-updated-delphi-logos.md | B40: Updated Delphi Logos | C40: 2008-09-05T20:17:35-06:00 | D40: Jim McKeeth | E40: News (232) | F40: 1 | G40: general
A41: 2008-09-29-audio-quality.md | B41: Audio Quality | C41: 2008-09-29T10:24:28-06:00 | D41: Jim McKeeth | E41: News (232) | F41: 1 | G41: general
A42: 2008-10-28-live-twitting-the-keynotes-at-pdc2008.md | B42: Live Twitting the Keynotes at PDC2008 | C42: 2008-10-28T10:36:59-06:00 | D42: Jim McKeeth | E42: News (232) | F42: 1 | G42: general
A43: 2008-11-06-revenge-of-delphi-robot-rage.md | B43: The Revenge of Delphi Robot Rage | C43: 2008-11-06T14:54:51-07:00 | D43: Jim McKeeth | E43: News (232) | F43: 1 | G43: general
A44: 2009-01-06-more-questions-for-nick-hodges.md | B44: More Questions for Nick Hodges | C44: 2009-01-06T04:26:56-07:00 | D44: Jim McKeeth | E44: News (232) | F44: 1 | G44: general
A45: 2009-01-28-refactor-my-delphi-code.md | B45: Refactor My Delphi Code | C45: 2009-01-28T13:50:08-07:00 | D45: Jim McKeeth | E45: News (232) | F45: 1 | G45: general
A46: 2009-02-09-21-remobjects.md | B46: 21 ? RemObjects | C46: 2009-02-09T23:59:05-07:00 | D46: Jim McKeeth | E46: News (232) | F46: 1 | G46: general
A47: 2009-02-10-whats-in-a-name.md | B47: What?s in a Language Name? | C47: 2009-02-10T19:31:59-07:00 | D47: Jim McKeeth | E47: News (232) | F47: 1 | G47: general
A48: 2009-03-19-delphi-weaver-beta-coming.md | B48: Delphi ?Weaver? Beta coming | C48: 2009-03-19T23:24:23-06:00 | D48: Jim McKeeth | E48: News (232) | F48: 1 | G48: general
A49: 2009-05-01-29-pawel-glowacki.md | B49: 29 ? Pawel Glowacki | C49: 2009-05-01T03:10:18-06:00 | D49: Jim McKeeth | E49: News (232) | F49: 1 | G49: general
...

Sheet index
B1: Count | C1: Tag | E1: Links
B2: {=_xlfn.HSTACK( _xlfn.SORTBY(_xlfn.UNIQUE(_xlfn.TOCOL(TRIM(_xlfn.TEXTSPLIT(metadata!E2:E1000, ",", , TRUE)), 3)), _xlfn.MAP(_xlfn.UNIQUE(_xlfn.TOCOL(TRIM(_xlfn.TEXTSPLIT(metadata!E2:E1000, ",", , TRUE)), 3)), _xlfn.LAMBDA(_xlpm.tag, COUNTIF(metadata!E2:E1000, "*"&_xlpm.tag&"*"))), -1), _xlfn.SORTBY(_xlfn.MAP(_xlfn.UNIQUE(_xlfn.TOCOL(TRIM(_xlfn.TEXTSPLIT(metadata!E2:E1000, ",", , TRUE)), 3)), _xlfn.LAMBDA(_xlpm.tag, COUNTIF(metadata!E2:E1000, "*"&_xlpm.tag&"*"))), _xlfn.MAP(_xlfn.UNIQUE(_xlfn.TOCOL(TRIM(_xlfn.TEXTSPLIT(metadata!E2:E1000, ",", , TRUE)), 3)), _xlfn.LAMBDA(_xlpm.tag, COUNTIF(metadata!E2:E1000, "*"&_xlpm.tag&"*"))), -1) )} -> News (232) | C2: 232 | E2: {=TRANSPOSE(_xlfn.TAKE(_xlfn.MAP( _xlfn._xlws.FILTER(metadata!B$2:B$410, ISNUMBER(SEARCH("*"&B2&"*", metadata!E$2:E$410))), _xlfn._xlws.FILTER(metadata!F$2:F$410, ISNUMBER(SEARCH("*"&B2&"*", metadata!E$2:E$410))), _xlfn._xlws.FILTER(ROW(metadata!B$2:B$410), ISNUMBER(SEARCH("*"&B2&"*", metadata!E$2:E$410))), _xlfn.LAMBDA(_xlpm.title,_xlpm.tag_count,_xlpm.row_num, HYPERLINK("#metadata!A"&_xlpm.row_num, "["&_xlpm.tag_count&"] "&_xlpm.title) ) ),10))} -> [1] Now on iTunes | F2: [1] Updated Delphi Logos | G2: [1] Audio Quality | H2: [1] Live Twitting the Keynotes at PDC2008 | I2: [1] The Revenge of Delphi Robot Rage | J2: [1] More Questions for Nick Hodges | K2: [1] Refactor My Delphi Code | L2: [1] 21 ? RemObjects | M2: [1] What?s in a Language Name? | N2: [1] Delphi ?Weaver? Beta coming
B3: delphi (91) | C3: 91 | E3: {=TRANSPOSE(_xlfn.TAKE(_xlfn.MAP( _xlfn._xlws.FILTER(metadata!B$2:B$410, ISNUMBER(SEARCH("*"&B3&"*", metadata!E$2:E$410))), _xlfn._xlws.FILTER(metadata!F$2:F$410, ISNUMBER(SEARCH("*"&B3&"*", metadata!E$2:E$410))), _xlfn._xlws.FILTER(ROW(metadata!B$2:B$410), ISNUMBER(SEARCH("*"&B3&"*", metadata!E$2:E$410))), _xlfn.LAMBDA(_xlpm.title,_xlpm.tag_count,_xlpm.row_num, HYPERLINK("#metadata!A"&_xlpm.row_num, "["&_xlpm.tag_count&"] "&_xlpm.title) ) ),10))} -> [2] 51 ? Nick Hodges | F3: [2] DelphiLive! Presentation Downloads | G3: [2] Delphi?s Big Day (with a little SVG fun!) | H3: [3] 6 ? Cast on News | I3: [3] 26 ? Dwitterphi | J3: [3] CodeRage C++ | K3: [3] Looking for a Delphi Syntax for TextMate | L3: [3] The First Computer Program ? In Delphi | M3: [3] Delphi Live! 2009 ? What is Cooking in the Delphi Labs ? Part 1 | N3: [3] Delphi could be 2008 Language of the Year
B4: Audio podCast (74) | C4: 74 | E4: {=TRANSPOSE(_xlfn.TAKE(_xlfn.MAP( _xlfn._xlws.FILTER(metadata!B$2:B$410, ISNUMBER(SEARCH("*"&B4&"*", metadata!E$2:E$410))), _xlfn._xlws.FILTER(metadata!F$2:F$410, ISNUMBER(SEARCH("*"&B4&"*", metadata!E$2:E$410))), _xlfn._xlws.FILTER(ROW(metadata!B$2:B$410), ISNUMBER(SEARCH("*"&B4&"*", metadata!E$2:E$410))), _xlfn.LAMBDA(_xlpm.title,_xlpm.tag_count,_xlpm.row_num, HYPERLINK("#metadata!A"&_xlpm.row_num, "["&_xlpm.tag_count&"] "&_xlpm.title) ) ),10))} -> [1] 22 ? Delphi Developer Days 2009 | F4: [1] 23 ? DataRage and All-Access | G4: [1] 43 ? Simon Kissel | H4: [1] 49 ? Gad D Lord and MTG Studio | I4: [1] 50 ? Tables Turned | J4: [1] 52 ? Marco Cantu & Delphi XE4 for iOS | K4: [1] 53 ? Subject 33 & Android Game Development | L4: [1] Also on the Tablet Show | M4: [2] 47 ? Marco & Cary ? Delphi Developer Days 2011 | N4: [2] 51 ? Nick Hodges
B5: podcast (63) | C5: 63 | E5: {=TRANSPOSE(_xlfn.TAKE(_xlfn.MAP( _xlfn._xlws.FILTER(metadata!B$2:B$410, ISNUMBER(SEARCH("*"&B5&"*", metadata!E$2:E$410))), _xlfn._xlws.FILTER(metadata!F$2:F$410, ISNUMBER(SEARCH("*"&B5&"*", metadata!E$2:E$410))), _xlfn._xlws.FILTER(ROW(metadata!B$2:B$410), ISNUMBER(SEARCH("*"&B5&"*", metadata!E$2:E$410))), _xlfn.LAMBDA(_xlpm.title,_xlpm.tag_count,_xlpm.row_num, HYPERLINK("#metadata!A"&_xlpm.row_num, "["&_xlpm.tag_count&"] "&_xlpm.title) ) ),10))} -> [2] 28 ? Ray Konopka | F5: [2] 34 ? Craig Stuntz | G5: [2] 40 ? Nick Hodges ? Part 1 | H5: [2] 44 ? Allen Bauer ? Part 1 of 2 | I5: [2] 45 ? Allen Bauer ? Part 2 of 2 | J5: [2] 48 ? Pascal Game Development with Jason McMillen | K5: [2] Episode 54 ? Sarina DuPont | L5: [2] Episode #55 ? Interview with JT | M5: [2] Interview with Darren Kosinski | N5: [2] Brian Alexakis and Virtual Reality
B6: Source Code (33) | C6: 33 | E6: {=TRANSPOSE(_xlfn.TAKE(_xlfn.MAP( _xlfn._xlws.FILTER(metadata!B$2:B$410, ISNUMBER(SEARCH("*"&B6&"*", metadata!E$2:E$410))), _xlfn._xlws.FILTER(metadata!F$2:F$410, ISNUMBER(SEARCH("*"&B6&"*", metadata!E$2:E$410))), _xlfn._xlws.FILTER(ROW(metadata!B$2:B$410), ISNUMBER(SEARCH("*"&B6&"*", metadata!E$2:E$410))), _xlfn.LAMBDA(_xlpm.title,_xlpm.tag_count,_xlpm.row_num, HYPERLINK("#metadata!A"&_xlpm.row_num, "["&_xlpm.tag_count&"] "&_xlpm.title) ) ),10))} -> [1] Mobile Location on iOS and Android | F6: [1] Hello Moto 360 from Delphi XE7 | G6: [1] Run Outside the Handler or Making a Non-Blocking Call | H6: [1] Factorials, Combinations & Permutaions | I6: [1] Deep Dive into Futures and the Parallel Programming Library | J6: [1] How to Reference a Procedure | K6: [1] Advanced HTTP Hacking Webinar Code | L6: [2] Every Android API for Delphi | M6: [2] CORS on DataSnap REST Server | N6: [2] FireDAC MemTable Editing ? New in 10.2 Tokyo
B7: Mobile (32) | C7: 32 | E7: {=TRANSPOSE(_xlfn.TAKE(_xlfn.MAP( _xlfn._xlws.FILTER(metadata!B$2:B$410, ISNUMBER(SEARCH("*"&B7&"*", metadata!E$2:E$410))), _xlfn._xlws.FILTER(metadata!F$2:F$410, ISNUMBER(SEARCH("*"&B7&"*", metadata!E$2:E$410))), _xlfn._xlws.FILTER(ROW(metadata!B$2:B$410), ISNUMBER(SEARCH("*"&B7&"*", metadata!E$2:E$410))), _xlfn.LAMBDA(_xlpm.title,_xlpm.tag_count,_xlpm.row_num, HYPERLINK("#metadata!A"&_xlpm.row_num, "["&_xlpm.tag_count&"] "&_xlpm.title) ) ),10))} -> [2] Fire UI and the Multi-Device Designer | F7: [2] Blackberry is Still Ahead of Microsoft | G7: [2] Reading Barcodes with XE5 ? Preliminary post | H7: [2] A Tale of Two Grids | I7: [2] Mobile Push Notifications without a BaaS | J7: [2] Delphi XE5 Android Device Compatibility | K7: [2] SysCheck for XE5 Compatibility | L7: [2] Android Fragmentation | M7: [2] What About Blackberry? | N7: [2] Voice Enable Your Android Apps
B8: Video podCast (31) | C8: 31 | E8: {=TRANSPOSE(_xlfn.TAKE(_xlfn.MAP( _xlfn._xlws.FILTER(metadata!B$2:B$410, ISNUMBER(SEARCH("*"&B8&"*", metadata!E$2:E$410))), _xlfn._xlws.FILTER(metadata!F$2:F$410, ISNUMBER(SEARCH("*"&B8&"*", metadata!E$2:E$410))), _xlfn._xlws.FILTER(ROW(metadata!B$2:B$410), ISNUMBER(SEARCH("*"&B8&"*", metadata!E$2:E$410))), _xlfn.LAMBDA(_xlpm.title,_xlpm.tag_count,_xlpm.row_num, HYPERLINK("#metadata!A"&_xlpm.row_num, "["&_xlpm.tag_count&"] "&_xlpm.title) ) ),10))} -> [1] LIVE! 13-Feb-2018 Delphi Web Frameworks | F8: [1] LIVE! Episode on Delphi Games and Graphics Engines | G8: [2] Video now included | H8: [2] LIVE! Tuesday, January 23rd, 2018 | I8: [2] LIVE! Episode Tuesday, January 30th, 2018 | J8: [2] Single Board Computers and Delphi Discussion LIVE! | K8: [2] LIVE! Monday at 9 AM PST ? Podcast Episode on Programming Books | L8: [2] Earlier this week?s episode on Cool Apps | M8: [2] LIVE! with TMS Software?s Bruno Fierens, Wagner Landgraf & Holger Flick | N8: [2] LIVE! from the Embarcadero Austin Office
B9: MVP (30) | C9: 30 | E9: {=TRANSPOSE(_xlfn.TAKE(_xlfn.MAP( _xlfn._xlws.FILTER(metadata!B$2:B$410, ISNUMBER(SEARCH("*"&B9&"*", metadata!E$2:E$410))), _xlfn._xlws.FILTER(metadata!F$2:F$410, ISNUMBER(SEARCH("*"&B9&"*", metadata!E$2:E$410))), _xlfn._xlws.FILTER(ROW(metadata!B$2:B$410), ISNUMBER(SEARCH("*"&B9&"*", metadata!E$2:E$410))), _xlfn.LAMBDA(_xlpm.title,_xlpm.tag_count,_xlpm.row_num, HYPERLINK("#metadata!A"&_xlpm.row_num, "["&_xlpm.tag_count&"] "&_xlpm.title) ) ),10))} -> [1] New Embarcadero MVPs | F9: [1] New MVPs & Directory | G9: [1] MVP Tweets of the Week ? April 26, 2015 | H9: [1] Meet the New Embarcadero MVPs | I9: [1] MVP of the Week: Jens Fudge | J9: [1] More New MVPs | K9: [1] MVP Spotlight: Cary Jensen | L9: [1] MVP Spotlight: Eli of FMXExpress.com | M9: [1] Meet HOSOKAWA Jun, our Japan MVP | N9: [2] What MVPs Are Saying about Delphi and C++Builder 10 Seattle
B10: iOS (26) | C10: 26 | E10: {=TRANSPOSE(_xlfn.TAKE(_xlfn.MAP( _xlfn._xlws.FILTER(metadata!B$2:B$410, ISNUMBER(SEARCH("*"&B10&"*", metadata!E$2:E$410))), _xlfn._xlws.FILTER(metadata!F$2:F$410, ISNUMBER(SEARCH("*"&B10&"*", metadata!E$2:E$410))), _xlfn._xlws.FILTER(ROW(metadata!B$2:B$410), ISNUMBER(SEARCH("*"&B10&"*", metadata!E$2:E$410))), _xlfn.LAMBDA(_xlpm.title,_xlpm.tag_count,_xlpm.row_num, HYPERLINK("#metadata!A"&_xlpm.row_num, "["&_xlpm.tag_count&"] "&_xlpm.title) ) ),10))} -> [1] My Favorite Quote from the XE5 Tour | F10: [2] Scanning Barcodes with RAD Studio XE5 | G10: [2] Blackberry is Still Ahead of Microsoft | H10: [2] Reading Barcodes with XE5 ? Preliminary post | I10: [2] A Tale of Two Grids | J10: [2] Mobile Push Notifications without a BaaS | K10: [2] The April 2017 Tokyo Hotfix Works with the new Xcode & iOS | L10: [2] Revisiting Google Glass | M10: [3] More on Android Services with Delphi 10 Seattle | N10: [3] TMS Pack for FireMonkey now supports XE5 and Android
B11: webinar (23) | C11: 23 | E11: {=TRANSPOSE(_xlfn.TAKE(_xlfn.MAP( _xlfn._xlws.FILTER(metadata!B$2:B$410, ISNUMBER(SEARCH("*"&B11&"*", metadata!E$2:E$410))), _xlfn._xlws.FILTER(metadata!F$2:F$410, ISNUMBER(SEARCH("*"&B11&"*", metadata!E$2:E$410))), _xlfn._xlws.FILTER(ROW(metadata!B$2:B$410), ISNUMBER(SEARCH("*"&B11&"*", metadata!E$2:E$410))), _xlfn.LAMBDA(_xlpm.title,_xlpm.tag_count,_xlpm.row_num, HYPERLINK("#metadata!A"&_xlpm.row_num, "["&_xlpm.tag_count&"] "&_xlpm.title) ) ),10))} -> [1] Data Visualization with Ray Konopka | F11: [1] How Delphi and C# Are More Alike Than You May Know | G11: [1] Integrate Cloud Services with the REST/JSON Client | H11: [1] Developer Skill Sprint: Effectively Using Delphi Generics with Ray Konopka | I11: [1] 3 Webinar Replays: Windows 10, Cool Apps & Migration | J11: [1] Delphi and the Blockchain: More than just Bitcoin and Cryptocurrency | K11: [2] Revisiting Google Glass | L11: [2] Delphi XE5 Mobile App Development Workshop | M11: [2] FireDAC In-Memory DataSet: TFDMemTable | N11: [2] FireDAC: Local SQL
B12: delphi prism (20) | C12: 20 | E12: {=TRANSPOSE(_xlfn.TAKE(_xlfn.MAP( _xlfn._xlws.FILTER(metadata!B$2:B$410, ISNUMBER(SEARCH("*"&B12&"*", metadata!E$2:E$410))), _xlfn._xlws.FILTER(metadata!F$2:F$410, ISNUMBER(SEARCH("*"&B12&"*", metadata!E$2:E$410))), _xlfn._xlws.FILTER(ROW(metadata!B$2:B$410), ISNUMBER(SEARCH("*"&B12&"*", metadata!E$2:E$410))), _xlfn.LAMBDA(_xlpm.title,_xlpm.tag_count,_xlpm.row_num, HYPERLINK("#metadata!A"&_xlpm.row_num, "["&_xlpm.tag_count&"] "&_xlpm.title) ) ),10))} -> [3] 19 ? Delphi Prism Q&A | F12: [3] Looking for a Delphi Syntax for TextMate | G12: [3] What is Delphi Prism? | H12: [4] Screencast 3 ? Delphi Prism first look | I12: [4] More on Delphi Prism | J12: [4] Screencast 4 ? Delphi Prism WPF ? Hello World | K12: [5] 12 ? Nick, marc & Allen on Delphi Prism | L12: [5] First Delphi Flash Mob at PDC2008 | M12: [5] Delphi Live! 2009 ? What is Cooking in the Delphi Labs ? Part 6 | N12: [6] Robot Rage SDK Available
B13: codegear (19) | C13: 19 | E13: {=TRANSPOSE(_xlfn.TAKE(_xlfn.MAP( _xlfn._xlws.FILTER(metadata!B$2:B$410, ISNUMBER(SEARCH("*"&B13&"*", metadata!E$2:E$410))), _xlfn._xlws.FILTER(metadata!F$2:F$410, ISNUMBER(SEARCH("*"&B13&"*", metadata!E$2:E$410))), _xlfn._xlws.FILTER(ROW(metadata!B$2:B$410), ISNUMBER(SEARCH("*"&B13&"*", metadata!E$2:E$410))), _xlfn.LAMBDA(_xlpm.title,_xlpm.tag_count,_xlpm.row_num, HYPERLINK("#metadata!A"&_xlpm.row_num, "["&_xlpm.tag_count&"] "&_xlpm.title) ) ),10))} -> [3] Code Rage III: Call for Speakers | F13: [3] The Further Adventures of Turboman | G13: [4] Delphi 2009 Available for Order | H13: [4] Delphi 2009 Updates 3 & 4 are in the Wild! | I13: [4] Screencast 3 ? Delphi Prism first look | J13: [5] 1 ? Tiburon | K13: [5] Return of Delphi Man | L13: [5] Delphi Live! 2009 ? What is Cooking in the Delphi Labs ? Part 2 | M13: [5] Interview with Nick Hodges | N13: [5] What?s going on here?
B14: Conferences (15) | C14: 15 | E14: {=TRANSPOSE(_xlfn.TAKE(_xlfn.MAP( _xlfn._xlws.FILTER(metadata!B$2:B$410, ISNUMBER(SEARCH("*"&B14&"*", metadata!E$2:E$410))), _xlfn._xlws.FILTER(metadata!F$2:F$410, ISNUMBER(SEARCH("*"&B14&"*", metadata!E$2:E$410))), _xlfn._xlws.FILTER(ROW(metadata!B$2:B$410), ISNUMBER(SEARCH("*"&B14&"*", metadata!E$2:E$410))), _xlfn.LAMBDA(_xlpm.title,_xlpm.tag_count,_xlpm.row_num, HYPERLINK("#metadata!A"&_xlpm.row_num, "["&_xlpm.tag_count&"] "&_xlpm.title) ) ),10))} -> [1] Delphi Bots Live! | F14: [1] Conference Time | G14: [1] CodeRage 8 Is Coming! | H14: [1] T-Shirts from Brazil Delphi Conference | I14: [2] 47 ? Marco & Cary ? Delphi Developer Days 2011 | J14: [2] Meet Me in Philly at the CodeCamp | K14: [2] Things I Learned from Delphi CodeRage 8 | L14: [2] Pictures from the 10.3 Rio Preview in Brazil | M14: [2] Stops on My North America Tour | N14: [2] Robert ?Uncle Bob? Martin is Speaking at CodeRage XII
... B16: coderage (12) | C16: 12 | E16: {=TRANSPOSE(_xlfn.TAKE(_xlfn.MAP( _xlfn._xlws.FILTER(metadata!B$2:B$410, ISNUMBER(SEARCH("*"&B16&"*", metadata!E$2:E$410))), _xlfn._xlws.FILTER(metadata!F$2:F$410, ISNUMBER(SEARCH("*"&B16&"*", metadata!E$2:E$410))), _xlfn._xlws.FILTER(ROW(metadata!B$2:B$410), ISNUMBER(SEARCH("*"&B16&"*", metadata!E$2:E$410))), _xlfn.LAMBDA(_xlpm.title,_xlpm.tag_count,_xlpm.row_num, HYPERLINK("#metadata!A"&_xlpm.row_num, "["&_xlpm.tag_count&"] "&_xlpm.title) ) ),10))} -> [2] Things I Learned from Delphi CodeRage 8 | F16: [2] CodeRage III Sessions and Registration | G16: [3] Code Rage III: Call for Speakers | H16: [4] 10 ? Marco Cant? | I16: [4] Delayed Exception Handling | J16: [6] Robot Rage SDK Available | K16: [6] Delphi Prism Silverlight Replay | L16: [7] 18 ? CodeRage III Wrap-Up | M16: [7] 16 ? CodeRage, Delphi RobotRage and Technology | N16: [8] 17 ? CodeRage III and WideOrbit
B17: devices (8) | C17: 8 | E17: {=TRANSPOSE(_xlfn.TAKE(_xlfn.MAP( _xlfn._xlws.FILTER(metadata!B$2:B$410, ISNUMBER(SEARCH("*"&B17&"*", metadata!E$2:E$410))), _xlfn._xlws.FILTER(metadata!F$2:F$410, ISNUMBER(SEARCH("*"&B17&"*", metadata!E$2:E$410))), _xlfn._xlws.FILTER(ROW(metadata!B$2:B$410), ISNUMBER(SEARCH("*"&B17&"*", metadata!E$2:E$410))), _xlfn.LAMBDA(_xlpm.title,_xlpm.tag_count,_xlpm.row_num, HYPERLINK("#metadata!A"&_xlpm.row_num, "["&_xlpm.tag_count&"] "&_xlpm.title) ) ),10))} -> [1] Delphi Sensors on Windows 8 Tablet | F17: [2] Developing on the Samsung Gear Live Smart Watch | G17: [3] The Craig Chapman IoT Episode | H17: [3] Google???s Project Brillo, Weave, and Delphi | I17: [3] The FireUI: Multi-Device Designer in RAD Studio XE7 | J17: [6] WebBroker on Android and Raspberry Pi 3 | K17: [7] Connecting Delphi to my Brain with the Emotiv EPOC | L17: [10] Connecting to the Parrot AR.Drone 2.0 from Delphi XE5
B18: .NET (8) | C18: 8 | E18: {=TRANSPOSE(_xlfn.TAKE(_xlfn.MAP( _xlfn._xlws.FILTER(metadata!B$2:B$410, ISNUMBER(SEARCH("*"&B18&"*", metadata!E$2:E$410))), _xlfn._xlws.FILTER(metadata!F$2:F$410, ISNUMBER(SEARCH("*"&B18&"*", metadata!E$2:E$410))), _xlfn._xlws.FILTER(ROW(metadata!B$2:B$410), ISNUMBER(SEARCH("*"&B18&"*", metadata!E$2:E$410))), _xlfn.LAMBDA(_xlpm.title,_xlpm.tag_count,_xlpm.row_num, HYPERLINK("#metadata!A"&_xlpm.row_num, "["&_xlpm.tag_count&"] "&_xlpm.title) ) ),10))} -> [3] ShineOn 1.0.1.0 Released | F18: [4] 5 ? Oxygene and .NET | G18: [6] 39 ? marc hoffman on Prism and Mac | H18: [6] Delphi Win32 and .NET Diverging | I18: [7] Cirrus Aspect Oriented Programming Replay | J18: [8] Anders Hejlsberg on Programming Languages | K18: [8] 15 ? Julian Bucknall on DevExpress | L18: [10] Delphi Prism / Oxygene Questions
B19: Delphi Projects (8) | C19: 8 | E19: {=TRANSPOSE(_xlfn.TAKE(_xlfn.MAP( _xlfn._xlws.FILTER(metadata!B$2:B$410, ISNUMBER(SEARCH("*"&B19&"*", metadata!E$2:E$410))), _xlfn._xlws.FILTER(metadata!F$2:F$410, ISNUMBER(SEARCH("*"&B19&"*", metadata!E$2:E$410))), _xlfn._xlws.FILTER(ROW(metadata!B$2:B$410), ISNUMBER(SEARCH("*"&B19&"*", metadata!E$2:E$410))), _xlfn.LAMBDA(_xlpm.title,_xlpm.tag_count,_xlpm.row_num, HYPERLINK("#metadata!A"&_xlpm.row_num, "["&_xlpm.tag_count&"] "&_xlpm.title) ) ),10))} -> [2] 24 ? Delphi Projects | F19: [3] Thought Controlled Quadcopter | G19: [3] The First Computer Program ? In Delphi | H19: [3] Learning from Digifort | I19: [3] Hello Google Glass from Delphi XE5 | J19: [4] Delphi XE5 Mobile REST Client Demo Source | K19: [4] Android Screen View | L19: [7] 27 ? Nick Hodges ? R&D Manager
B20: community (8) | C20: 8 | E20: {=TRANSPOSE(_xlfn.TAKE(_xlfn.MAP( _xlfn._xlws.FILTER(metadata!B$2:B$410, ISNUMBER(SEARCH("*"&B20&"*", metadata!E$2:E$410))), _xlfn._xlws.FILTER(metadata!F$2:F$410, ISNUMBER(SEARCH("*"&B20&"*", metadata!E$2:E$410))), _xlfn._xlws.FILTER(ROW(metadata!B$2:B$410), ISNUMBER(SEARCH("*"&B20&"*", metadata!E$2:E$410))), _xlfn.LAMBDA(_xlpm.title,_xlpm.tag_count,_xlpm.row_num, HYPERLINK("#metadata!A"&_xlpm.row_num, "["&_xlpm.tag_count&"] "&_xlpm.title) ) ),10))} -> [4] Lino Tadros? Gift of Life | F20: [4] The Stack Overflow Delphi Badge | G20: [5] Delphi Legends 2009 Community Award | H20: [5] Delphi Keeps Climbing | I20: [5] Delphi Live! 2010 ? Call for Papers | J20: [5] Caused Stack Overflow | K20: [7] Torry?s Updates | L20: [7] TIOBE: Delphi in top 10 again after strong comeback
B21: Article (7) | C21: 7 | E21: {=TRANSPOSE(_xlfn.TAKE(_xlfn.MAP( _xlfn._xlws.FILTER(metadata!B$2:B$410, ISNUMBER(SEARCH("*"&B21&"*", metadata!E$2:E$410))), _xlfn._xlws.FILTER(metadata!F$2:F$410, ISNUMBER(SEARCH("*"&B21&"*", metadata!E$2:E$410))), _xlfn._xlws.FILTER(ROW(metadata!B$2:B$410), ISNUMBER(SEARCH("*"&B21&"*", metadata!E$2:E$410))), _xlfn.LAMBDA(_xlpm.title,_xlpm.tag_count,_xlpm.row_num, HYPERLINK("#metadata!A"&_xlpm.row_num, "["&_xlpm.tag_count&"] "&_xlpm.title) ) ),10))} -> [1] Tips for Solving Bugs | F21: [1] What is Delphi?s DNA? | G21: [2] More on 1Password?s Components | H21: [2] Law of the Instrument and Curse of the Programmer | I21: [2] Get Ready for the New Programmers! | J21: [3] FireMonkey and the Android Misconception | K21: [10] Delphi Prism / Oxygene Questions
B22: FireMonkey (7) | C22: 7 | E22: {=TRANSPOSE(_xlfn.TAKE(_xlfn.MAP( _xlfn._xlws.FILTER(metadata!B$2:B$410, ISNUMBER(SEARCH("*"&B22&"*", metadata!E$2:E$410))), _xlfn._xlws.FILTER(metadata!F$2:F$410, ISNUMBER(SEARCH("*"&B22&"*", metadata!E$2:E$410))), _xlfn._xlws.FILTER(ROW(metadata!B$2:B$410), ISNUMBER(SEARCH("*"&B22&"*", metadata!E$2:E$410))), _xlfn.LAMBDA(_xlpm.title,_xlpm.tag_count,_xlpm.row_num, HYPERLINK("#metadata!A"&_xlpm.row_num, "["&_xlpm.tag_count&"] "&_xlpm.title) ) ),10))} -> [2] The Year of the FireMonkey | F22: [4] FireMonkey vs. VCL | G22: [4] Skill Sprint: Using FireMonkey Layouts | H22: [4] Why I Keep Choosing Delphi | I22: [5] Android Z-Order, Native Controls, and 10.3 Rio | J22: [5] 3D Credits Scroll with Delphi | K22: [8] The Niagara Falls Lighting Episode
B23: gadgets (7) | C23: 7 | E23: {=TRANSPOSE(_xlfn.TAKE(_xlfn.MAP( _xlfn._xlws.FILTER(metadata!B$2:B$410, ISNUMBER(SEARCH("*"&B23&"*", metadata!E$2:E$410))), _xlfn._xlws.FILTER(metadata!F$2:F$410, ISNUMBER(SEARCH("*"&B23&"*", metadata!E$2:E$410))), _xlfn._xlws.FILTER(ROW(metadata!B$2:B$410), ISNUMBER(SEARCH("*"&B23&"*", metadata!E$2:E$410))), _xlfn.LAMBDA(_xlpm.title,_xlpm.tag_count,_xlpm.row_num, HYPERLINK("#metadata!A"&_xlpm.row_num, "["&_xlpm.tag_count&"] "&_xlpm.title) ) ),10))} -> [2] Connecting the Philips Hue Bridge to Wi-Fi | F23: [3] Thought Controlled Quadcopter | G23: [3] BlueTooth Remote Control Car | H23: [4] Parrot AR.Drone 2.0 Delphi Component | I23: [5] Connecting to the Kinect for Windows with RAD Studio XE5 | J23: [7] Connecting Delphi to my Brain with the Emotiv EPOC | K23: [10] Connecting to the Parrot AR.Drone 2.0 from Delphi XE5
B24: conference (7) | C24: 7 | E24: {=TRANSPOSE(_xlfn.TAKE(_xlfn.MAP( _xlfn._xlws.FILTER(metadata!B$2:B$410, ISNUMBER(SEARCH("*"&B24&"*", metadata!E$2:E$410))), _xlfn._xlws.FILTER(metadata!F$2:F$410, ISNUMBER(SEARCH("*"&B24&"*", metadata!E$2:E$410))), _xlfn._xlws.FILTER(ROW(metadata!B$2:B$410), ISNUMBER(SEARCH("*"&B24&"*", metadata!E$2:E$410))), _xlfn.LAMBDA(_xlpm.title,_xlpm.tag_count,_xlpm.row_num, HYPERLINK("#metadata!A"&_xlpm.row_num, "["&_xlpm.tag_count&"] "&_xlpm.title) ) ),10))} -> [4] Delphi Live! Date Updated | F24: [5] 20 ? Introducing Delphi Live 2009 | G24: [5] 25 ? DelphiLive! | H24: [5] 42 ? David I | I24: [5] Delphi Live! 2010 ? Call for Papers | J24: [7] 38 ? Marco & Cary | K24: [9] DelphiLive! Speaker Series
B25: design (5) | C25: 5 | E25: {=TRANSPOSE(_xlfn.TAKE(_xlfn.MAP( _xlfn._xlws.FILTER(metadata!B$2:B$410, ISNUMBER(SEARCH("*"&B25&"*", metadata!E$2:E$410))), _xlfn._xlws.FILTER(metadata!F$2:F$410, ISNUMBER(SEARCH("*"&B25&"*", metadata!E$2:E$410))), _xlfn._xlws.FILTER(ROW(metadata!B$2:B$410), ISNUMBER(SEARCH("*"&B25&"*", metadata!E$2:E$410))), _xlfn.LAMBDA(_xlpm.title,_xlpm.tag_count,_xlpm.row_num, HYPERLINK("#metadata!A"&_xlpm.row_num, "["&_xlpm.tag_count&"] "&_xlpm.title) ) ),10))} -> [1] Know Your Alignments | F25: [2] Fire UI and the Multi-Device Designer | G25: [3] Skeuomorphic No More? | H25: [3] Looking at Radiant Shapes | I25: [4] FireMonkey vs. VCL
B26: FireDAC (5) | C26: 5 | E26: {=TRANSPOSE(_xlfn.TAKE(_xlfn.MAP( _xlfn._xlws.FILTER(metadata!B$2:B$410, ISNUMBER(SEARCH("*"&B26&"*", metadata!E$2:E$410))), _xlfn._xlws.FILTER(metadata!F$2:F$410, ISNUMBER(SEARCH("*"&B26&"*", metadata!E$2:E$410))), _xlfn._xlws.FILTER(ROW(metadata!B$2:B$410), ISNUMBER(SEARCH("*"&B26&"*", metadata!E$2:E$410))), _xlfn.LAMBDA(_xlpm.title,_xlpm.tag_count,_xlpm.row_num, HYPERLINK("#metadata!A"&_xlpm.row_num, "["&_xlpm.tag_count&"] "&_xlpm.title) ) ),10))} -> [1] Simple Mobile FireDAC App | F26: [3] Getting Technical with Cary Jensen and FireDAC (Episode 74) | G26: [4] MongoDB FireDAC C++ Sample | H26: [4] API Limits with #FDEC | I26: [6] Export Trello to CSV
B27: Funny (5) | C27: 5 | E27: {=TRANSPOSE(_xlfn.TAKE(_xlfn.MAP( _xlfn._xlws.FILTER(metadata!B$2:B$410, ISNUMBER(SEARCH("*"&B27&"*", metadata!E$2:E$410))), _xlfn._xlws.FILTER(metadata!F$2:F$410, ISNUMBER(SEARCH("*"&B27&"*", metadata!E$2:E$410))), _xlfn._xlws.FILTER(ROW(metadata!B$2:B$410), ISNUMBER(SEARCH("*"&B27&"*", metadata!E$2:E$410))), _xlfn.LAMBDA(_xlpm.title,_xlpm.tag_count,_xlpm.row_num, HYPERLINK("#metadata!A"&_xlpm.row_num, "["&_xlpm.tag_count&"] "&_xlpm.title) ) ),10))} -> [1] 6 Stages of Debugging | F27: [2] Exceptionally Bad Exception Abuse | G27: [4] Code Monkey in Delphi Code | H27: [5] 3D Credits Scroll with Delphi | I27: [6] The Worst Thing About Delphi
A28: devices | B28: Brain Computer Interface (5) | C28: 5 | E28: {=TRANSPOSE(_xlfn.TAKE(_xlfn.MAP( _xlfn._xlws.FILTER(metadata!B$2:B$410, ISNUMBER(SEARCH("*"&B28&"*", metadata!E$2:E$410))), _xlfn._xlws.FILTER(metadata!F$2:F$410, ISNUMBER(SEARCH("*"&B28&"*", metadata!E$2:E$410))), _xlfn._xlws.FILTER(ROW(metadata!B$2:B$410), ISNUMBER(SEARCH("*"&B28&"*", metadata!E$2:E$410))), _xlfn.LAMBDA(_xlpm.title,_xlpm.tag_count,_xlpm.row_num, HYPERLINK("#metadata!A"&_xlpm.row_num, "["&_xlpm.tag_count&"] "&_xlpm.title) ) ),10))} -> [2] Meet Me in Philly at the CodeCamp | F28: [3] Meet Me in Chicago & D.C./Baltimore for a First Look at XE6 | G28: [3] Thought Controlled Quadcopter | H28: [7] Connecting Delphi to my Brain with the Emotiv EPOC | I28: [10] Connecting to the Parrot AR.Drone 2.0 from Delphi XE5
B29: Components (5) | C29: 5 | E29: {=TRANSPOSE(_xlfn.TAKE(_xlfn.MAP( _xlfn._xlws.FILTER(metadata!B$2:B$410, ISNUMBER(SEARCH("*"&B29&"*", metadata!E$2:E$410))), _xlfn._xlws.FILTER(metadata!F$2:F$410, ISNUMBER(SEARCH("*"&B29&"*", metadata!E$2:E$410))), _xlfn._xlws.FILTER(ROW(metadata!B$2:B$410), ISNUMBER(SEARCH("*"&B29&"*", metadata!E$2:E$410))), _xlfn.LAMBDA(_xlpm.title,_xlpm.tag_count,_xlpm.row_num, HYPERLINK("#metadata!A"&_xlpm.row_num, "["&_xlpm.tag_count&"] "&_xlpm.title) ) ),10))} -> [2] Scanning Barcodes with RAD Studio XE5 | F29: [3] TMS Pack for FireMonkey now supports XE5 and Android | G29: [4] Parrot AR.Drone 2.0 Delphi Component | H29: [4] Indispensable Delphi Libraries | I29: [7] Torry?s Updates
A30: architecture | B30: Architecture (4) | C30: 4 | E30: {=TRANSPOSE(_xlfn.TAKE(_xlfn.MAP( _xlfn._xlws.FILTER(metadata!B$2:B$410, ISNUMBER(SEARCH("*"&B30&"*", metadata!E$2:E$410))), _xlfn._xlws.FILTER(metadata!F$2:F$410, ISNUMBER(SEARCH("*"&B30&"*", metadata!E$2:E$410))), _xlfn._xlws.FILTER(ROW(metadata!B$2:B$410), ISNUMBER(SEARCH("*"&B30&"*", metadata!E$2:E$410))), _xlfn.LAMBDA(_xlpm.title,_xlpm.tag_count,_xlpm.row_num, HYPERLINK("#metadata!A"&_xlpm.row_num, "["&_xlpm.tag_count&"] "&_xlpm.title) ) ),10))} -> [1] Why Some Mobile Apps are So Slow | F30: [1] MVVM-MVC-RAD Architectures with ColumbusEgg4Delphi | G30: [2] Exceptionally Bad Exception Abuse | H30: [4] Parallel For Loops
B31: Commentary (4) | C31: 4 | E31: {=TRANSPOSE(_xlfn.TAKE(_xlfn.MAP( _xlfn._xlws.FILTER(metadata!B$2:B$410, ISNUMBER(SEARCH("*"&B31&"*", metadata!E$2:E$410))), _xlfn._xlws.FILTER(metadata!F$2:F$410, ISNUMBER(SEARCH("*"&B31&"*", metadata!E$2:E$410))), _xlfn._xlws.FILTER(ROW(metadata!B$2:B$410), ISNUMBER(SEARCH("*"&B31&"*", metadata!E$2:E$410))), _xlfn.LAMBDA(_xlpm.title,_xlpm.tag_count,_xlpm.row_num, HYPERLINK("#metadata!A"&_xlpm.row_num, "["&_xlpm.tag_count&"] "&_xlpm.title) ) ),10))} -> [1] Sum(Programming Languages) > 0 | F31: [1] How to Get Answers to Your Questions | G31: [5] The Delphi Object Pascal Language | H31: [5] Hidden features in the Delphi Object Pascal language
B32: Graphics (4) | C32: 4 | E32: {=TRANSPOSE(_xlfn.TAKE(_xlfn.MAP( _xlfn._xlws.FILTER(metadata!B$2:B$410, ISNUMBER(SEARCH("*"&B32&"*", metadata!E$2:E$410))), _xlfn._xlws.FILTER(metadata!F$2:F$410, ISNUMBER(SEARCH("*"&B32&"*", metadata!E$2:E$410))), _xlfn._xlws.FILTER(ROW(metadata!B$2:B$410), ISNUMBER(SEARCH("*"&B32&"*", metadata!E$2:E$410))), _xlfn.LAMBDA(_xlpm.title,_xlpm.tag_count,_xlpm.row_num, HYPERLINK("#metadata!A"&_xlpm.row_num, "["&_xlpm.tag_count&"] "&_xlpm.title) ) ),10))} -> [1] Directions to iPhone, Windows & OS X | F32: [1] Delphi XE5 Android Wallpaper | G32: [2] C++Builder XE6 for Android Wallpaper | H32: [4] OpenGL ES Support on Mobile with XE6
A33: android | B33: Android-Services (4) | C33: 4 | E33: {=TRANSPOSE(_xlfn.TAKE(_xlfn.MAP( _xlfn._xlws.FILTER(metadata!B$2:B$410, ISNUMBER(SEARCH("*"&B33&"*", metadata!E$2:E$410))), _xlfn._xlws.FILTER(metadata!F$2:F$410, ISNUMBER(SEARCH("*"&B33&"*", metadata!E$2:E$410))), _xlfn._xlws.FILTER(ROW(metadata!B$2:B$410), ISNUMBER(SEARCH("*"&B33&"*", metadata!E$2:E$410))), _xlfn.LAMBDA(_xlpm.title,_xlpm.tag_count,_xlpm.row_num, HYPERLINK("#metadata!A"&_xlpm.row_num, "["&_xlpm.tag_count&"] "&_xlpm.title) ) ),10))} -> [2] Minimalistic Android Service with Delphi 10 Seattle | F33: [2] Another Android Background Services Video | G33: [3] Android Services Presentations and Workarounds | H33: [3] More on Android Services with Delphi 10 Seattle
A34: x | B34: Delphi programming (4) | C34: 4 | E34: {=TRANSPOSE(_xlfn.TAKE(_xlfn.MAP( _xlfn._xlws.FILTER(metadata!B$2:B$410, ISNUMBER(SEARCH("*"&B34&"*", metadata!E$2:E$410))), _xlfn._xlws.FILTER(metadata!F$2:F$410, ISNUMBER(SEARCH("*"&B34&"*", metadata!E$2:E$410))), _xlfn._xlws.FILTER(ROW(metadata!B$2:B$410), ISNUMBER(SEARCH("*"&B34&"*", metadata!E$2:E$410))), _xlfn.LAMBDA(_xlpm.title,_xlpm.tag_count,_xlpm.row_num, HYPERLINK("#metadata!A"&_xlpm.row_num, "["&_xlpm.tag_count&"] "&_xlpm.title) ) ),10))} -> [5] Delphi Makes #8 on TPCI | F34: [7] Episode 13 ? Allen Bauer live at PDC2008 | G34: [10] Delphi Prism / Oxygene Questions | H34: [10] Getting the Latest JCL and JVCL
B35: Cloud (3) | C35: 3 | E35: {=TRANSPOSE(_xlfn.TAKE(_xlfn.MAP( _xlfn._xlws.FILTER(metadata!B$2:B$410, ISNUMBER(SEARCH("*"&B35&"*", metadata!E$2:E$410))), _xlfn._xlws.FILTER(metadata!F$2:F$410, ISNUMBER(SEARCH("*"&B35&"*", metadata!E$2:E$410))), _xlfn._xlws.FILTER(ROW(metadata!B$2:B$410), ISNUMBER(SEARCH("*"&B35&"*", metadata!E$2:E$410))), _xlfn.LAMBDA(_xlpm.title,_xlpm.tag_count,_xlpm.row_num, HYPERLINK("#metadata!A"&_xlpm.row_num, "["&_xlpm.tag_count&"] "&_xlpm.title) ) ),10))} -> [1] Google Cloud Shell Network Details | F35: [4] API Limits with #FDEC | G35: [5] Using TMS Cloud Pack to Integrate Your Apps with the Cloud
A36: devices | B36: Internet of Things (3) | C36: 3 | E36: {=TRANSPOSE(_xlfn.TAKE(_xlfn.MAP( _xlfn._xlws.FILTER(metadata!B$2:B$410, ISNUMBER(SEARCH("*"&B36&"*", metadata!E$2:E$410))), _xlfn._xlws.FILTER(metadata!F$2:F$410, ISNUMBER(SEARCH("*"&B36&"*", metadata!E$2:E$410))), _xlfn._xlws.FILTER(ROW(metadata!B$2:B$410), ISNUMBER(SEARCH("*"&B36&"*", metadata!E$2:E$410))), _xlfn.LAMBDA(_xlpm.title,_xlpm.tag_count,_xlpm.row_num, HYPERLINK("#metadata!A"&_xlpm.row_num, "["&_xlpm.tag_count&"] "&_xlpm.title) ) ),10))} -> [1] What is the Internet of Things? | F36: [3] Google???s Project Brillo, Weave, and Delphi | G36: [4] Cool App Contender: HOP (Hunger Obesity Prevention) App
B37: Cool Apps (3) | C37: 3 | E37: {=TRANSPOSE(_xlfn.TAKE(_xlfn.MAP( _xlfn._xlws.FILTER(metadata!B$2:B$410, ISNUMBER(SEARCH("*"&B37&"*", metadata!E$2:E$410))), _xlfn._xlws.FILTER(metadata!F$2:F$410, ISNUMBER(SEARCH("*"&B37&"*", metadata!E$2:E$410))), _xlfn._xlws.FILTER(ROW(metadata!B$2:B$410), ISNUMBER(SEARCH("*"&B37&"*", metadata!E$2:E$410))), _xlfn.LAMBDA(_xlpm.title,_xlpm.tag_count,_xlpm.row_num, HYPERLINK("#metadata!A"&_xlpm.row_num, "["&_xlpm.tag_count&"] "&_xlpm.title) ) ),10))} -> [2] Cool App Contender: Network Fool Card Game | F37: [2] Cool App Contender: SUMOTORI DE CHU | G37: [8] The Niagara Falls Lighting Episode
B38: Debugging (3) | C38: 3 | E38: {=TRANSPOSE(_xlfn.TAKE(_xlfn.MAP( _xlfn._xlws.FILTER(metadata!B$2:B$410, ISNUMBER(SEARCH("*"&B38&"*", metadata!E$2:E$410))), _xlfn._xlws.FILTER(metadata!F$2:F$410, ISNUMBER(SEARCH("*"&B38&"*", metadata!E$2:E$410))), _xlfn._xlws.FILTER(ROW(metadata!B$2:B$410), ISNUMBER(SEARCH("*"&B38&"*", metadata!E$2:E$410))), _xlfn.LAMBDA(_xlpm.title,_xlpm.tag_count,_xlpm.row_num, HYPERLINK("#metadata!A"&_xlpm.row_num, "["&_xlpm.tag_count&"] "&_xlpm.title) ) ),10))} -> [2] 8 Tips to Speed Up Your Android ARM Emulator (AVD) | F38: [3] Debugging Against a Remote Android Emulator | G38: [7] 10 Reasons to Use PAServer for Remote Windows Deployment
B39: 10.3 Rio (3) | C39: 3 | E39: {=TRANSPOSE(_xlfn.TAKE(_xlfn.MAP( _xlfn._xlws.FILTER(metadata!B$2:B$410, ISNUMBER(SEARCH("*"&B39&"*", metadata!E$2:E$410))), _xlfn._xlws.FILTER(metadata!F$2:F$410, ISNUMBER(SEARCH("*"&B39&"*", metadata!E$2:E$410))), _xlfn._xlws.FILTER(ROW(metadata!B$2:B$410), ISNUMBER(SEARCH("*"&B39&"*", metadata!E$2:E$410))), _xlfn.LAMBDA(_xlpm.title,_xlpm.tag_count,_xlpm.row_num, HYPERLINK("#metadata!A"&_xlpm.row_num, "["&_xlpm.tag_count&"] "&_xlpm.title) ) ),10))} -> [3] Get the Most out of Android with 10.3 Rio | F39: [5] Android Z-Order, Native Controls, and 10.3 Rio | G39: [6] Unexpected Benefit of Inline Variables: Conditional Blocks
B40: beyond compare (3) | C40: 3 | E40: {=TRANSPOSE(_xlfn.TAKE(_xlfn.MAP( _xlfn._xlws.FILTER(metadata!B$2:B$410, ISNUMBER(SEARCH("*"&B40&"*", metadata!E$2:E$410))), _xlfn._xlws.FILTER(metadata!F$2:F$410, ISNUMBER(SEARCH("*"&B40&"*", metadata!E$2:E$410))), _xlfn._xlws.FILTER(ROW(metadata!B$2:B$410), ISNUMBER(SEARCH("*"&B40&"*", metadata!E$2:E$410))), _xlfn.LAMBDA(_xlpm.title,_xlpm.tag_count,_xlpm.row_num, HYPERLINK("#metadata!A"&_xlpm.row_num, "["&_xlpm.tag_count&"] "&_xlpm.title) ) ),10))} -> [3] Craig Peterson?s favorite blog links | F40: [7] 2 ? Nick Hodges | G40: [9] 7 ? Beyond Compare
B41: DataBase (3) | C41: 3 | E41: {=TRANSPOSE(_xlfn.TAKE(_xlfn.MAP( _xlfn._xlws.FILTER(metadata!B$2:B$410, ISNUMBER(SEARCH("*"&B41&"*", metadata!E$2:E$410))), _xlfn._xlws.FILTER(metadata!F$2:F$410, ISNUMBER(SEARCH("*"&B41&"*", metadata!E$2:E$410))), _xlfn._xlws.FILTER(ROW(metadata!B$2:B$410), ISNUMBER(SEARCH("*"&B41&"*", metadata!E$2:E$410))), _xlfn.LAMBDA(_xlpm.title,_xlpm.tag_count,_xlpm.row_num, HYPERLINK("#metadata!A"&_xlpm.row_num, "["&_xlpm.tag_count&"] "&_xlpm.title) ) ),10))} -> [3] New Delphi Seattle MongoDB Sample | F41: [4] MongoDB FireDAC C++ Sample | G41: [6] Export Trello to CSV
...
